<?xml version="1.0"?>
<robot name="madar">

    <!-- BEGIN: T-STRUCTURE -->
    <link name="madar_base_link">
        <visual>
            <geometry>
                <mesh filename="/visual/platform/estructura_asm.dae"/>
            </geometry>
        </visual>
        <collision>
            <origin xyz="0 0 0.375" rpy="0 0 0"/>
            <geometry>
                <cylinder radius="0.4" length="0.75"/>
            </geometry>
        </collision>
        <collision>
            <origin xyz="0 0 1.395" rpy="0 0 0"/>
            <geometry>
                <box size="0.5 0.08 0.05"/>
            </geometry>
        </collision>
        <collision>
            <origin xyz="0 0 1.056" rpy="0 0 0"/>
            <geometry>
                <box size="0.08 0.08 0.63"/>
            </geometry>
        </collision>
        <collision>
            <origin xyz="0 -0.14 0.916" rpy="0 0 0" />
            <geometry>
                <box size="0.43 0.2 0.33"/>
            </geometry>
        </collision>
    </link>
    <!-- END: T-STRUCTURE -->

    <!-- END: WHEELS -->
    <joint name="motor_1" type="continuous">
      <parent link="madar_base_link"/>
      <child link="wheel_1_link"/>
      <axis xyz="-1 0 0"/>
      <origin rpy="2.0944 0 1.5708" xyz="0 -0.2905 0.1"/>
    </joint>
  
    <link name="wheel_1_link">
      <visual>
        <geometry>
            <mesh filename="/visual/platform/wheel.dae"/>
        </geometry>
      </visual>
      <collision>
        <geometry>
          <sphere radius="0.10"/>
        </geometry>
      </collision>
      <inertial>
         <mass value="10"/>
         <inertia ixx="0.04" ixy="0" ixz="0" iyy="0.04" iyz="0" izz="0.04"/> <!-- Provisional inertia values -->
       </inertial>
    </link>
  
    <joint name="motor_2" type="continuous">
      <parent link="madar_base_link"/>
      <child link="wheel_2_link"/>
      <axis xyz="-1 0 0"/>
      <origin rpy="0 0 3.66519" xyz="0.25158 0.14525 0.1"/>
    </joint>
  
    <link name="wheel_2_link">
      <visual>
        <geometry>
            <mesh filename="/visual/platform/wheel.dae"/>
        </geometry>
      </visual>
      <collision>
        <geometry>
          <sphere radius="0.10"/>
        </geometry>
      </collision>
      <inertial>
         <mass value="10"/>
         <inertia ixx="0.04" ixy="0" ixz="0" iyy="0.04" iyz="0" izz="0.04"/>
       </inertial>
    </link>
  
    <joint name="motor_3" type="continuous">
      <parent link="madar_base_link"/>
      <child link="wheel_3_link"/>
      <axis xyz="-1 0 0"/>
      <origin rpy="0 0 5.75959" xyz="-0.25158 0.14525 0.1"/>
    </joint>
  
    <link name="wheel_3_link">
      <visual>
        <geometry>
            <mesh filename="/visual/platform/wheel.dae"/>
        </geometry>
      </visual>
      <collision>
        <geometry>
          <sphere radius="0.10"/>
        </geometry>
      </collision>
      <inertial>
         <mass value="10"/>
         <inertia ixx="0.04" ixy="0" ixz="0" iyy="0.04" iyz="0" izz="0.04"/>
       </inertial>
    </link>
  
    <!-- END: WHEELS -->

    <!-- BEGIN: ARM RIGHT -->

    <joint name="right_arm_base_fixed_joint" type="fixed">
        <parent link="madar_base_link"/>
        <child link="right_arm_base_link"/>
        <origin xyz="0.256 0.0 1.389" rpy="3.142 -0.7874 0.000"/>
    </joint>

    <link name="right_arm_base_link">
        <visual>
            <origin xyz="0 0 0" rpy="0 0 3.14159"/>
            <geometry>
                <mesh filename="/visual/ur5/base.dae"/>
            </geometry>
        </visual>
        <collision>
            <origin xyz="0 0 0" rpy="0 0 3.14159"/>
            <geometry>
                <mesh filename="/collision/ur5/base.stl"/>
            </geometry>
        </collision>
        <inertial>
            <mass value="4.0000"/>
            <inertia ixx="0.00443333156" ixy="0" ixz="0" iyy="0.00443333156" iyz="0" izz="0.0072"/>
        </inertial>
    </link>
    
    <joint name="right_shoulder_pan_joint" type="revolute">
        <parent link="right_arm_base_link"/>
        <child link="right_shoulder_link"/>
        <origin xyz="0 0 0.089159" rpy="0 0 0"/>
        <axis xyz="0 0 1"/>
        <limit effort="150" lower="-6.2831853" upper="6.2831853" velocity="3.14159"/>
    </joint>
    
    <link name="right_shoulder_link">
        <visual>
            <origin xyz="0 0 0" rpy="0 0 3.14159"/>
            <geometry>
                <mesh filename="/visual/ur5/shoulder.dae"/>
            </geometry>
        </visual>
        <collision>
            <origin xyz="0 0 0" rpy="0 0 3.14159"/>
            <geometry>
                <mesh filename="/collision/ur5/shoulder.stl"/>
            </geometry>
        </collision>
        <inertial>
            <mass value="3.7000"/>
            <inertia ixx="0.010267495893" ixy="0" ixz="0" iyy="0.010267495893" iyz="0" izz="0.00666"/>
        </inertial>
    </link>
    
    <joint name="right_shoulder_lift_joint" type="revolute">
        <parent link="right_shoulder_link"/>
        <child link="right_upper_arm_link"/>
        <origin xyz="0 0 0" rpy="1.570796327 0 0"/>
        <axis xyz="0 0 1"/>
        <limit effort="150" lower="-6.2831853" upper="6.2831853" velocity="3.14159"/>
    </joint>
    
    <link name="right_upper_arm_link">
        <visual>
            <origin xyz="0 0 0.13585" rpy="1.57079 0 -1.57079"/>
            <geometry>
                <mesh filename="/visual/ur5/upperarm.dae"/>
            </geometry>
        </visual>
        <collision>
            <origin xyz="0 0 0.13585" rpy="1.57079 0 -1.57079"/>
            <geometry>
                <mesh filename="/collision/ur5/upperarm.stl"/>
            </geometry>
        </collision>
        <inertial>
          <mass value="8.3930"/>
          <origin xyz="0 0 0.28"/>
          <inertia ixx="0.22689067591" ixy="0" ixz="0" iyy="0.22689067591" iyz="0" izz="0.0151074"/>
        </inertial>
    </link>
    
    <joint name="right_elbow_joint" type="revolute">
        <parent link="right_upper_arm_link"/>
        <child link="right_fore_arm_link"/>
        <origin xyz="-0.425 0 0" rpy="0 0 0"/>
        <axis xyz="0 0 1"/>
        <limit effort="150" lower="-6.2831853" upper="6.2831853" velocity="3.14159"/>
        <!-- <limit effort="150" lower="-3.14159" upper="3.14159" velocity="3.14159"/> -->
    </joint>
    
    <link name="right_fore_arm_link">
        <visual>
            <origin xyz="0 0 0.0165" rpy="1.57079 0 -1.57079"/>
            <geometry>
                <mesh filename="/visual/ur5/forearm.dae"/>
            </geometry>
        </visual>
        <collision>
            <origin xyz="0 0 0.0165" rpy="1.57079 0 -1.57079"/>
            <geometry>
                <mesh filename="/collision/ur5/forearm.stl"/>
            </geometry>
        </collision>
        <inertial>
            <mass value="2.3300"/>
            <origin xyz="0 0 0.25"/>
            <inertia ixx="0.049443313556" ixy="0" ixz="0" iyy="0.049443313556" iyz="0" izz="0.004095"/>
        </inertial>
    </link>
    
    <joint name="right_wrist_1_joint" type="revolute">
        <parent link="right_fore_arm_link"/>
        <child link="right_wrist_1_link"/>
        <origin xyz="-0.39225 0 0.10915" rpy="0 0 0"/>
        <axis xyz="0 0 1"/>
        <limit effort="28" lower="-6.2831853" upper="6.2831853" velocity="3.14159"/>
      </joint>
    
    <link name="right_wrist_1_link">
        <visual>
            <origin xyz="0 0 -0.093" rpy="1.57079 0 0"/>
            <geometry>
                <mesh filename="/visual/ur5/wrist1.dae"/>
            </geometry>
        </visual>
        <collision>
            <origin xyz="0 0 -0.093" rpy="1.57079 0 0"/>
            <geometry>
                <mesh filename="/collision/ur5/wrist1.stl"/>
            </geometry>
        </collision>
        <inertial>
            <mass value="1.2190"/>
            <inertia ixx="0.111172755531" ixy="0" ixz="0" iyy="0.111172755531" iyz="0" izz="0.21942"/>
        </inertial>
    </link>
    
    <joint name="right_wrist_2_joint" type="revolute">
        <parent link="right_wrist_1_link"/>
        <child link="right_wrist_2_link"/>
        <origin xyz="0 -0.09465 -1.941303950897609e-11" rpy="1.570796327 0 0"/>
        <axis xyz="0 0 1"/>
        <limit effort="28" lower="-6.2831853" upper="6.2831853" velocity="3.14159"/>
    </joint>
    
    <link name="right_wrist_2_link">
        <visual>
            <origin xyz="0 0 -0.095" rpy="0 0 0"/>
            <geometry>
                <mesh filename="/visual/ur5/wrist2.dae"/>
            </geometry>
        </visual>
        <collision>
            <origin xyz="0 0 -0.095" rpy="0 0 0"/>
            <geometry>
                <mesh filename="/collision/ur5/wrist2.stl"/>
            </geometry>
        </collision>
        <inertial>
            <mass value="1.2190"/>
            <inertia ixx="0.111172755531" ixy="0" ixz="0" iyy="0.111172755531" iyz="0" izz="0.21942"/>
        </inertial>
    </link>
    
    <joint name="right_wrist_3_joint" type="revolute">
        <parent link="right_wrist_2_link"/>
        <child link="right_wrist_3_link"/>
        <origin xyz="0 0.0823 -1.688001216681175e-11" rpy="1.570796326589793 3.141592653589793 3.141592653589793"/>
        <axis xyz="0 0 1"/>
        <limit effort="28" lower="-6.2831853" upper="6.2831853" velocity="3.14159"/>
    </joint>
    
    <link name="right_wrist_3_link">
        <visual>
            <origin xyz="0 0 -0.0818" rpy="1.57079 0 0"/>
            <geometry>
                <mesh filename="/visual/ur5/wrist3.dae"/>
            </geometry>
        </visual>
        <collision>
            <origin xyz="0 0 -0.0818" rpy="1.57079 0 0"/>
            <geometry>
                <mesh filename="/collision/ur5/wrist3.stl"/>
            </geometry>
        </collision>
        <inertial>
            <mass value="0.1879"/>
            <inertia ixx="0.0171364731454" ixy="0" ixz="0" iyy="0.0171364731454" iyz="0" izz="0.033822"/>
        </inertial>
    </link>

    <!-- END: ARM RIGHT -->

    <!-- BEGIN: ARM LEFT -->

    <joint name="left_arm_base_fixed_joint" type="fixed">
        <parent link="madar_base_link"/>
        <child link="left_arm_base_link"/>
        <origin xyz="-0.256 0.0 1.389" rpy="-3.142 0.7874 0.000"/>
    </joint>

    <link name="left_arm_base_link">
        <visual>
            <origin xyz="0 0 0" rpy="0 0 3.14159"/>
            <geometry>
                <mesh filename="/visual/ur5/base.dae"/>
            </geometry>
        </visual>
        <collision>
            <origin xyz="0 0 0" rpy="0 0 3.14159"/>
            <geometry>
                <mesh filename="/collision/ur5/base.stl"/>
            </geometry>
        </collision>
        <inertial>
            <mass value="4.0000"/>
            <inertia ixx="0.00443333156" ixy="0" ixz="0" iyy="0.00443333156" iyz="0" izz="0.0072"/>
        </inertial>
    </link>
    
    <joint name="left_shoulder_pan_joint" type="revolute">
        <parent link="left_arm_base_link"/>
        <child link="left_shoulder_link"/>
        <origin xyz="0 0 0.089159" rpy="0 0 0"/>
        <axis xyz="0 0 1"/>
        <limit effort="150" lower="-6.2831853" upper="6.2831853" velocity="3.14159"/>
    </joint>
    
    <link name="left_shoulder_link">
        <visual>
            <origin xyz="0 0 0" rpy="0 0 3.14159"/>
            <geometry>
                <mesh filename="/visual/ur5/shoulder.dae"/>
            </geometry>
        </visual>
        <collision>
            <origin xyz="0 0 0" rpy="0 0 3.14159"/>
            <geometry>
                <mesh filename="/collision/ur5/shoulder.stl"/>
            </geometry>
        </collision>
        <inertial>
            <mass value="3.7000"/>
            <inertia ixx="0.010267495893" ixy="0" ixz="0" iyy="0.010267495893" iyz="0" izz="0.00666"/>
        </inertial>
    </link>
    
    <joint name="left_shoulder_lift_joint" type="revolute">
        <parent link="left_shoulder_link"/>
        <child link="left_upper_arm_link"/>
        <origin xyz="0 0 0" rpy="1.570796327 0 0"/>
        <axis xyz="0 0 1"/>
        <limit effort="150" lower="-6.2831853" upper="6.2831853" velocity="3.14159"/>
    </joint>
    
    <link name="left_upper_arm_link">
        <visual>
            <origin xyz="0 0 0.13585" rpy="1.57079 0 -1.57079"/>
            <geometry>
                <mesh filename="/visual/ur5/upperarm.dae"/>
            </geometry>
        </visual>
        <collision>
            <origin xyz="0 0 0.13585" rpy="1.57079 0 -1.57079"/>
            <geometry>
                <mesh filename="/collision/ur5/upperarm.stl"/>
            </geometry>
        </collision>
        <inertial>
          <mass value="8.3930"/>
          <origin xyz="0 0 0.28"/>
          <inertia ixx="0.22689067591" ixy="0" ixz="0" iyy="0.22689067591" iyz="0" izz="0.0151074"/>
        </inertial>
    </link>
    
    <joint name="left_elbow_joint" type="revolute">
        <parent link="left_upper_arm_link"/>
        <child link="left_fore_arm_link"/>
        <origin xyz="-0.425 0 0" rpy="0 0 0"/>
        <axis xyz="0 0 1"/>
        <limit effort="150" lower="-6.2831853" upper="6.2831853" velocity="3.14159"/>
    </joint>
    
    <link name="left_fore_arm_link">
        <visual>
            <origin xyz="0 0 0.0165" rpy="1.57079 0 -1.57079"/>
            <geometry>
                <mesh filename="/visual/ur5/forearm.dae"/>
            </geometry>
        </visual>
        <collision>
            <origin xyz="0 0 0.0165" rpy="1.57079 0 -1.57079"/>
            <geometry>
                <mesh filename="/collision/ur5/forearm.stl"/>
            </geometry>
        </collision>
        <inertial>
            <mass value="2.3300"/>
            <origin xyz="0 0 0.25"/>
            <inertia ixx="0.049443313556" ixy="0" ixz="0" iyy="0.049443313556" iyz="0" izz="0.004095"/>
        </inertial>
    </link>
    
    <joint name="left_wrist_1_joint" type="revolute">
        <parent link="left_fore_arm_link"/>
        <child link="left_wrist_1_link"/>
        <origin xyz="-0.39225 0 0.10915" rpy="0 0 0"/>
        <axis xyz="0 0 1"/>
        <limit effort="28" lower="-6.2831853" upper="6.2831853" velocity="3.14159"/>
      </joint>
    
    <link name="left_wrist_1_link">
        <visual>
            <origin xyz="0 0 -0.093" rpy="1.57079 0 0"/>
            <geometry>
                <mesh filename="/visual/ur5/wrist1.dae"/>
            </geometry>
        </visual>
        <collision>
            <origin xyz="0 0 -0.093" rpy="1.57079 0 0"/>
            <geometry>
                <mesh filename="/collision/ur5/wrist1.stl"/>
            </geometry>
        </collision>
        <inertial>
            <mass value="1.2190"/>
            <inertia ixx="0.111172755531" ixy="0" ixz="0" iyy="0.111172755531" iyz="0" izz="0.21942"/>
        </inertial>
    </link>
    
    <joint name="left_wrist_2_joint" type="revolute">
        <parent link="left_wrist_1_link"/>
        <child link="left_wrist_2_link"/>
        <origin xyz="0 -0.09465 -1.941303950897609e-11" rpy="1.570796327 0 0"/>
        <axis xyz="0 0 1"/>
        <limit effort="28" lower="-6.2831853" upper="6.2831853" velocity="3.14159"/>
    </joint>
    
    <link name="left_wrist_2_link">
        <visual>
            <origin xyz="0 0 -0.095" rpy="0 0 0"/>
            <geometry>
                <mesh filename="/visual/ur5/wrist2.dae"/>
            </geometry>
        </visual>
        <collision>
            <origin xyz="0 0 -0.095" rpy="0 0 0"/>
            <geometry>
                <mesh filename="/collision/ur5/wrist2.stl"/>
            </geometry>
        </collision>
        <inertial>
            <mass value="1.2190"/>
            <inertia ixx="0.111172755531" ixy="0" ixz="0" iyy="0.111172755531" iyz="0" izz="0.21942"/>
        </inertial>
    </link>
    
    <joint name="left_wrist_3_joint" type="revolute">
        <parent link="left_wrist_2_link"/>
        <child link="left_wrist_3_link"/>
        <origin xyz="0 0.0823 -1.688001216681175e-11" rpy="1.570796326589793 3.141592653589793 3.141592653589793"/>
        <axis xyz="0 0 1"/>
        <limit effort="28" lower="-6.2831853" upper="6.2831853" velocity="3.14159"/>
    </joint>
    
    <link name="left_wrist_3_link">
        <visual>
            <origin xyz="0 0 -0.0818" rpy="1.57079 0 0"/>
            <geometry>
                <mesh filename="/visual/ur5/wrist3.dae"/>
            </geometry>
        </visual>
        <collision>
            <origin xyz="0 0 -0.0818" rpy="1.57079 0 0"/>
            <geometry>
                <mesh filename="/collision/ur5/wrist3.stl"/>
            </geometry>
        </collision>
        <inertial>
            <mass value="0.1879"/>
            <inertia ixx="0.0171364731454" ixy="0" ixz="0" iyy="0.0171364731454" iyz="0" izz="0.033822"/>
        </inertial>
    </link>

    <!-- END: ARM LEFT -->

    <!-- BEGIN: HAND RIGHT -->

    <joint name="right_hand_adapter_joint" type="fixed">
        <parent link="right_wrist_3_link"/>
        <child link="right_hand_adapter_link"/>
        <origin xyz="0 0 0.0225" rpy="0 0 0"/>
    </joint>

    <link name="right_hand_adapter_link" >
        <visual>
            <origin xyz="0 0 0" rpy="0 0 0" />
            <geometry>
                <cylinder radius="0.035" length="0.045"/>
            </geometry>
            <material name="LightGrey">
                <color rgba="0.7 0.7 0.7 1.0"/>
            </material>
        </visual>
        <collision>
            <origin xyz="0 0 0" rpy="0 0 0" />
            <geometry>
                <cylinder radius="0.035" length="0.045"/>
            </geometry>
        </collision>
    </link>

    <joint name="right_hand_support_joint" type="fixed">
        <parent link="right_hand_adapter_link"/>
        <child link="right_hand_base_link"/>
        <origin xyz="0.0 0.01 0.1175" rpy="0.0 0.0 1.570796326589793" />
    </joint>

    <link name="right_hand_base_link">
        <visual>
            <geometry>
                <mesh filename="/collision/allegro_hand/base_link_right.stl"/>
            </geometry>
            <origin rpy="0 0 0" xyz="0 0 0 "/>
            <material name="black">
                <color rgba="0.2 0.2 0.2 1"/>
            </material>
        </visual>
        <collision>
            <origin rpy="0 0 0" xyz="0 0 0"/>
            <geometry>
                <mesh filename="/collision/allegro_hand/base_link_right.stl"/>
            </geometry>
        </collision>
    </link>
    
    <!-- Thumb -->
    <link name="right_link_12_0">
        <visual>
            <geometry>
                <mesh filename="/collision/allegro_hand/link_12.0_right.STL"/>
            </geometry>
            <material name="black">
            <color rgba=".2 .2 .2 1"/>
            </material>
        </visual>
        <collision>
            <geometry>
                <box size="0.0358 0.034 0.0455"/>
            </geometry>
            <origin rpy="0 0 0" xyz="-0.0179 0.009 0.0145"/>
        </collision>
    </link>

    <link name="right_link_13_0">
        <visual>
            <geometry>
                <mesh filename="/collision/allegro_hand/link_13.0.STL"/>
            </geometry>
            <material name="black">
                <color rgba=".2 .2 .2 1"/>
            </material>
        </visual>
        <collision>
            <geometry>
                <box size="0.0196 0.0275 0.0177"/>
            </geometry>
            <origin rpy="0 0 0" xyz="0 0 0.00885"/>
        </collision>
    </link>

    <link name="right_link_14_0">
        <visual>
            <geometry>
                <mesh filename="/collision/allegro_hand/link_14.0.STL"/>
            </geometry>
            <material name="black">
            </material>
        </visual>
        <collision>
            <geometry>
                <box size="0.0196 0.0275 0.0514"/>
            </geometry>
            <origin rpy="0 0 0" xyz="0 0 0.0257"/>
        </collision>
    </link>

    <link name="right_link_15_0">
        <visual>
            <geometry>
                <mesh filename="/collision/allegro_hand/link_15.0.STL"/>
            </geometry>
            <material name="black">
            </material>
        </visual>
        <collision>
            <geometry>
                <box size="0.0196 0.0275 0.0423"/>
            </geometry>
            <origin rpy="0 0 0" xyz="0 0 0.02115"/>
        </collision> 
    </link>

    <!-- Index -->
    <link name="right_link_0_0">
        <visual>
            <geometry>
                <mesh filename="/collision/allegro_hand/link_0.0.STL"/>
            </geometry>
            <material name="black"/>
        </visual>
        <collision>
            <geometry>
                <box size="0.0196 0.0275 0.0164"/>
            </geometry>
            <origin rpy="0 0 0" xyz="0 0 0.0082"/>
        </collision>
    </link>

    <link name="right_link_1_0">
        <visual>
            <geometry>
                <mesh filename="/collision/allegro_hand/link_1.0.STL"/>
            </geometry>
            <material name="black"/>
        </visual>
        <collision>
            <geometry>
                <box size="0.0196 0.0275 0.054"/>
            </geometry>
            <origin rpy="0 0 0" xyz="0 0 0.027"/>
        </collision>
    </link>

    <link name="right_link_2_0">
        <visual>
            <geometry>
                <mesh filename="/collision/allegro_hand/link_2.0.STL"/>
            </geometry>
            <material name="black"/>
        </visual>
        <collision>
            <geometry>
                <box size="0.0196 0.0275 0.0384"/>
            </geometry>
            <origin rpy="0 0 0" xyz="0 0 0.0192"/>
        </collision>
      </link>

    <link name="right_link_3_0">
        <visual>
            <geometry>
                <mesh filename="/collision/allegro_hand/link_3.0.STL"/>
            </geometry>
            <material name="black"/>
        </visual>
        <collision>
            <geometry>
                <box size="0.0196 0.0275 0.0267"/>
            </geometry>
            <origin rpy="0 0 0" xyz="0 0 0.01335"/>
        </collision>
    </link>

    <!-- Middle -->
    <link name="right_link_4_0">
        <visual>
            <geometry>
                <mesh filename="/collision/allegro_hand/link_0.0.STL"/>
            </geometry>
            <material name="black"/>
        </visual>
        <collision>
            <geometry>
                <box size="0.0196 0.0275 0.0164"/>
            </geometry>
            <origin rpy="0 0 0" xyz="0 0 0.0082"/>
        </collision>
    </link>

    <link name="right_link_5_0">
        <visual>
            <geometry>
                <mesh filename="/collision/allegro_hand/link_1.0.STL"/>
            </geometry>
            <material name="black"/>
        </visual>
        <collision>
            <geometry>
                <box size="0.0196 0.0275 0.054"/>
            </geometry>
            <origin rpy="0 0 0" xyz="0 0 0.027"/>
        </collision>
    </link>

    <link name="right_link_6_0">
        <visual>
            <geometry>
                <mesh filename="/collision/allegro_hand/link_2.0.STL"/>
            </geometry>
            <material name="black"/>
        </visual>
        <collision>
            <geometry>
                <box size="0.0196 0.0275 0.0384"/>
            </geometry>
            <origin rpy="0 0 0" xyz="0 0 0.0192"/>
        </collision>
    </link>

    <link name="right_link_7_0">
        <visual>
            <geometry>
                <mesh filename="/collision/allegro_hand/link_3.0.STL"/>
            </geometry>
            <material name="black"/>
        </visual>
        <collision>
            <geometry>
                <box size="0.0196 0.0275 0.0267"/>
            </geometry>
            <origin rpy="0 0 0" xyz="0 0 0.01335"/>
        </collision>
    </link>

      <!-- Ring -->
    <link name="right_link_8_0">
        <visual>
            <geometry>
                <mesh filename="/collision/allegro_hand/link_0.0.STL"/>
            </geometry>
            <material name="black"/>
        </visual>
        <collision>
            <geometry>
                <box size="0.0196 0.0275 0.0164"/>
            </geometry>
            <origin rpy="0 0 0" xyz="0 0 0.0082"/>
        </collision>
      </link>

    <link name="right_link_9_0">
        <visual>
            <geometry>
                <mesh filename="/collision/allegro_hand/link_1.0.STL"/>
            </geometry>
            <material name="black"/>
        </visual>
        <collision>
            <geometry>
                <box size="0.0196 0.0275 0.054"/>
            </geometry>
            <origin rpy="0 0 0" xyz="0 0 0.027"/>
        </collision>
    </link>

    <link name="right_link_10_0">
        <visual>
            <geometry>
                <mesh filename="/collision/allegro_hand/link_2.0.STL"/>
            </geometry>
            <material name="black"/>
        </visual>
        <collision>
            <geometry>
                <box size="0.0196 0.0275 0.0384"/>
            </geometry>
            <origin rpy="0 0 0" xyz="0 0 0.0192"/>
        </collision>
    </link>

    <link name="right_link_11_0">
        <visual>
            <geometry>
                <mesh filename="/collision/allegro_hand/link_3.0.STL"/>
            </geometry>
            <material name="black"/>
        </visual>
        <collision>
            <geometry>
                <box size="0.0196 0.0275 0.0267"/>
            </geometry>
            <origin rpy="0 0 0" xyz="0 0 0.01335"/>
        </collision>
    </link>

    <!-- ################################################# -->
    <!-- JOINTS -->
    <!-- INDEX FINGER -->
    <joint name="right_joint_0_0" type="revolute">
        <axis xyz="0 0 +1"/>
        <limit effort="0.7" lower="-0.596932245164993" upper="0.588070723111615" velocity="3"/>
        <parent link="right_hand_base_link"/>
        <child link="right_link_0_0"/>
        <origin rpy="-0.08726646255 0 0" xyz="0 0.0435 -0.001542"/>
        <dynamics damping="0.021307336803783977" friction="0.06754533316058077"/>
    </joint>

    <joint name="right_joint_1_0" type="revolute">
        <limit effort="0.7" lower="-0.284219635541756" upper="1.79806052068398" velocity="3"/>
        <axis xyz="0 +1 0"/>
        <parent link="right_link_0_0"/>
        <child link="right_link_1_0"/>
        <origin xyz="0 0 0.0164"/>
        <dynamics damping="0.01767730238754802" friction="0.046834261267951538"/>
    </joint>

    <joint name="right_joint_2_0" type="revolute">
        <axis xyz="0 +1 0"/>
        <limit effort="0.7" lower="-0.277444047727987" upper="1.77295534050938" velocity="3"/>
        <parent link="right_link_1_0"/>
        <child link="right_link_2_0"/>
        <origin xyz="0 0 0.054"/>
        <dynamics damping="0.031774638864325758" friction="0.016627969777092133"/>
    </joint>

    <joint name="right_joint_3_0" type="revolute">
        <axis xyz="0 +1 0"/>
        <limit effort="0.7" lower="-0.282000556563447" upper="1.76086875700753" velocity="3"/>
        <parent link="right_link_2_0"/>
        <child link="right_link_3_0"/>
        <origin xyz="0 0 0.0384"/>
        <dynamics damping="0.038319998323206518" friction="0.021242402695969654"/>
    </joint>

    <!-- MIDDLE FINGER -->
    <joint name="right_joint_4_0" type="revolute">
        <axis xyz="0 0 +1"/>
        <limit effort="0.7" lower="-0.596932245164993" upper="0.588070723111615" velocity="3"/>
        <parent link="right_hand_base_link"/>
        <child link="right_link_4_0"/>
        <origin rpy="0.0 0 0" xyz="0 0 0.0007"/>
        <dynamics damping="0.03919965995816594" friction="0.039832089332686435"/>
    </joint>

    <joint name="right_joint_5_0" type="revolute">
        <limit effort="0.7" lower="-0.284219635541756" upper="1.79806052068398" velocity="3"/>
        <axis xyz="0 +1 0"/>
        <parent link="right_link_4_0"/>
        <child link="right_link_5_0"/>
        <origin xyz="0 0 0.0164"/>
        <dynamics damping="0.03873626118353872" friction="0.054137945660864321"/>
    </joint>

    <joint name="right_joint_6_0" type="revolute">
        <axis xyz="0 +1 0"/>
        <limit effort="0.7" lower="-0.277444047727987" upper="1.77295534050938" velocity="3"/>
        <parent link="right_link_5_0"/>
        <child link="right_link_6_0"/>
        <origin xyz="0 0 0.054"/>
        <dynamics damping="0.038096107794554551" friction="0.016501055223839444"/>
    </joint>

    <joint name="right_joint_7_0" type="revolute">
        <axis xyz="0 +1 0"/>
        <limit effort="0.7" lower="-0.282000556563447" upper="1.76086875700753" velocity="3"/>
        <parent link="right_link_6_0"/>
        <child link="right_link_7_0"/>
        <origin xyz="0 0 0.0384"/>
        <dynamics damping="0.030909594496839752" friction="0.018861768610753726"/>
    </joint>

    <!-- RING FINGER  -->
    <joint name="right_joint_8_0" type="revolute">
        <axis xyz="0 0 +1"/>
        <limit effort="0.7" lower="-0.596932245164993" upper="0.588070723111615" velocity="3"/>
        <parent link="right_hand_base_link"/>
        <child link="right_link_8_0"/>
        <origin rpy="0.08726646255 0 0" xyz="0 -0.0435 -0.001542"/>
        <dynamics damping="0.021307336803783977" friction="0.06754533316058077"/>
    </joint>

    <joint name="right_joint_9_0" type="revolute">
        <limit effort="0.7" lower="-0.284219635541756" upper="1.79806052068398" velocity="3"/>
        <axis xyz="0 +1 0"/>
        <parent link="right_link_8_0"/>
        <child link="right_link_9_0"/>
        <origin xyz="0 0 0.0164"/>
        <dynamics damping="0.01767730238754802" friction="0.046834261267951538"/>
    </joint>

    <joint name="right_joint_10_0" type="revolute">
        <axis xyz="0 +1 0"/>
        <limit effort="0.7" lower="-0.277444047727987" upper="1.77295534050938" velocity="3"/>
        <parent link="right_link_9_0"/>
        <child link="right_link_10_0"/>
        <origin xyz="0 0 0.054"/>
        <dynamics damping="0.031774638864325758" friction="0.016627969777092133"/>
    </joint>

    <joint name="right_joint_11_0" type="revolute">
        <axis xyz="0 +1 0"/>
        <limit effort="0.7" lower="-0.282000556563447" upper="1.76086875700753" velocity="3"/>
        <parent link="right_link_10_0"/>
        <child link="right_link_11_0"/>
        <origin xyz="0 0 0.0384"/>
        <dynamics damping="0.038319998323206518" friction="0.021242402695969654"/>
    </joint>

    <!-- THUMB FINGER -->
    <joint name="right_joint_12_0" type="revolute">
        <axis xyz="-1 0 0"/>
        <limit effort="0.7" lower="0.218668042522522" upper="1.53293975821553" velocity="3"/>
        <parent link="right_hand_base_link"/>
        <child link="right_link_12_0"/>
        <origin rpy="0 -1.65806278845 -1.5707963259" xyz="-0.0182 0.019333 -0.045987"/>
    </joint>

    <joint name="right_joint_13_0" type="revolute">
        <axis xyz="0 0 +1"/>
        <limit effort="0.7" lower="-0.396993229219395" upper="1.20296271414105" velocity="3"/>
        <parent link="right_link_12_0"/>
        <child link="right_link_13_0"/>
        <origin xyz="-0.027 0.005 0.0399"/>
    </joint>

    <joint name="right_joint_14_0" type="revolute">
        <axis xyz="0 +1 0"/>
        <limit effort="0.7" lower="-0.251244121924091" upper="1.76700820884751" velocity="3"/>
        <parent link="right_link_13_0"/>
        <child link="right_link_14_0"/>
        <origin xyz="0 0 0.0177"/>
    </joint>

    <joint name="right_joint_15_0" type="revolute">
        <axis xyz="0 +1 0"/>
        <limit effort="0.7" lower="-0.260209200996458" upper="1.82261832804392" velocity="3"/>
        <parent link="right_link_14_0"/>
        <child link="right_link_15_0"/>
        <origin xyz="0 0 0.0514"/>
    </joint>


    <!-- INDEX FINGER TIP -->
    <joint name="right_joint_3_0_tip" type="fixed">
        <parent link="right_link_3_0"/>
        <child link="right_link_3_0_tip"/>
        <origin rpy="0 0 0" xyz="0.01335 0 0.0408"/>
    </joint>

    <link name="right_link_3_0_tip">
        <visual>
            <geometry>
                <mesh filename="/collision/allegro_hand/sensing_tip.stl" scale="0.001 0.001 0.001"/>
            </geometry>
            <origin rpy="1.5708 0 1.5708" xyz="-0.0095 0 0"/>
            <material name="white">
                <color rgba="0.9 0.9 0.9 1"/>
            </material>
        </visual>
        <collision>
            <geometry>
                <sphere radius="0.012"/>
            </geometry>
        </collision>
    </link>
    
    <!-- MIDDLE FINGER TIP -->
    <joint name="right_joint_7_0_tip" type="fixed">
        <parent link="right_link_7_0"/>
        <child link="right_link_7_0_tip"/>
        <origin rpy="0 0 0" xyz="0.01335 0 0.0408"/>
    </joint>

    <link name="right_link_7_0_tip">
        <visual>
            <geometry>
                <mesh filename="/collision/allegro_hand/sensing_tip.stl" scale="0.001 0.001 0.001"/>
            </geometry>
            <origin rpy="1.5708 0 1.5708" xyz="-0.0095 0 0"/>
            <material name="white">
                <color rgba="0.9 0.9 0.9 1"/>
            </material>
        </visual>
        <collision>
            <geometry>
                <sphere radius="0.012"/>
            </geometry>
        </collision>
    </link>


  <!-- RING FINGER TIP -->
    <joint name="right_joint_11_0_tip" type="fixed">
        <parent link="right_link_11_0"/>
        <child link="right_link_11_0_tip"/>
        <origin rpy="0 0 0" xyz="0.01335 0 0.0408"/>
    </joint>

    <link name="right_link_11_0_tip">
        <visual>
            <geometry>
                <mesh filename="/collision/allegro_hand/sensing_tip.stl" scale="0.001 0.001 0.001"/>
            </geometry>
            <origin rpy="1.5708 0 1.5708" xyz="-0.0095 0 0"/>
            <material name="white">
                <color rgba="0.9 0.9 0.9 1"/>
            </material>
        </visual>
        <collision>
            <geometry>
                <sphere radius="0.012"/>
            </geometry>
        </collision>
    </link>

  <!-- THUMB TIP -->
    <joint name="right_joint_15_0_tip" type="fixed">
        <parent link="right_link_15_0"/>
        <child link="right_link_15_0_tip"/>
        <origin rpy="0 0 0" xyz="0.01335 0 0.0564"/>
    </joint>
    
    <link name="right_link_15_0_tip">
        <visual>
            <geometry>
                <mesh filename="/collision/allegro_hand/sensing_tip.stl" scale="0.001 0.001 0.001"/>
            </geometry>
            <origin rpy="1.5708 0 1.5708" xyz="-0.0095 0 0"/>
            <material name="white">
                <color rgba="0.9 0.9 0.9 1"/>
            </material>
        </visual>
        <collision>
            <geometry>
                <sphere radius="0.012"/>
            </geometry>
        </collision>
    </link>

      
    <!-- END: HAND RIGHT -->

    <!-- BEGIN: HAND LEFT -->


    <joint name="lefl_hand_adapter_joint" type="fixed">
        <parent link="left_wrist_3_link"/>
        <child link="left_hand_adapter_link"/>
        <origin xyz="0 0 0.0225" rpy="0 0 0"/>
    </joint>

    <link name="left_hand_adapter_link" >
        <visual>
            <origin xyz="0 0 0" rpy="0 0 0" />
            <geometry>
                <cylinder radius="0.035" length="0.045"/>
            </geometry>
            <material name="LightGrey">
                <color rgba="0.7 0.7 0.7 1.0"/>
            </material>
        </visual>
        <collision>
            <origin xyz="0 0 0" rpy="0 0 0" />
            <geometry>
                <cylinder radius="0.035" length="0.045"/>
            </geometry>
        </collision>
    </link>

    <joint name="left_hand_support_joint" type="fixed">
        <parent link="left_hand_adapter_link"/>
        <child link="left_hand_base_link"/>
        <origin xyz="0.0 0.01 0.1175" rpy="0.0 0.0 1.570796326589793" />
    </joint>

    <link name="left_hand_base_link">
        <visual>
            <geometry>
                <mesh filename="/collision/allegro_hand/base_link_left.stl"/>
            </geometry>
            <origin rpy="-1.5707963259 0 0" xyz="0 0 0 "/>
            <material name="black">
                <color rgba="0.2 0.2 0.2 1"/>
            </material>
        </visual>
        <collision>
            <origin rpy="-1.5707963259 0 0" xyz="0 0 0"/>
            <geometry>
                <mesh filename="/collision/allegro_hand/base_link_left.stl"/>
            </geometry>
        </collision>
    </link>

    <!-- Index -->

    <joint name="left_joint_0_0" type="revolute">
        <axis xyz="0 0 1" />
        <limit effort="0.7" lower="-0.5969322452" upper="0.588070723111615" velocity="3" />
        <parent link="left_hand_base_link" />
        <child link="left_link_0_0" />
        <origin rpy="0.08726646255 0 0" xyz="0 -0.0435 -0.001542" />
        <dynamics damping="0.021307336803783977" friction="0.06754533316058077" />
    </joint>

    <link name="left_link_0_0">
        <visual>
            <geometry>
                <mesh filename="/collision/allegro_hand/link_0.0.STL" />
            </geometry>
            <material name="black" />
        </visual>
        <collision>
            <geometry>
                <box size="0.0196 0.0275 0.0164" />
            </geometry>
            <origin rpy="0 0 0" xyz="0 0 0.0082" />
        </collision>
    </link>

    <joint name="left_joint_1_0" type="revolute">
        <limit effort="0.7" lower="-0.284219635541756" upper="1.79806052068398" velocity="3" />
        <axis xyz="0 1 0" />
        <parent link="left_link_0_0" />
        <child link="left_link_1_0" />
        <origin xyz="0 0 0.0164" />
        <dynamics damping="0.01767730238754802" friction="0.046834261267951538" />
    </joint>

    <link name="left_link_1_0">
        <visual>
            <geometry>
                <mesh filename="/collision/allegro_hand/link_1.0.STL" />
            </geometry>
            <material name="black" />
        </visual>
        <collision>
            <geometry>
                <box size="0.0196 0.0275 0.054" />
            </geometry>
            <origin rpy="0 0 0" xyz="0 0 0.027" />
        </collision>
    </link>

    <joint name="left_joint_2_0" type="revolute">
        <axis xyz="0 1 0" />
        <limit effort="0.7" lower="-0.277444047727987" upper="1.77295534050938" velocity="3" />
        <parent link="left_link_1_0" />
        <child link="left_link_2_0" />
        <origin xyz="0 0 0.054" />
        <dynamics damping="0.031774638864325758" friction="0.016627969777092133" />
    </joint>

    <link name="left_link_2_0">
        <visual>
            <geometry>
                <mesh filename="/collision/allegro_hand/link_2.0.STL" />
            </geometry>
            <material name="black" />
        </visual>
        <collision>
            <geometry>
                <box size="0.0196 0.0275 0.0384" />
            </geometry>
            <origin rpy="0 0 0" xyz="0 0 0.0192" />
        </collision>
    </link>

    <joint name="left_joint_3_0" type="revolute">
        <axis xyz="0 1 0" />
        <limit effort="0.7" lower="-0.282000556563447" upper="1.76086875700753" velocity="3" />
        <parent link="left_link_2_0" />
        <child link="left_link_3_0" />
        <origin xyz="0 0 0.0384" />
        <dynamics damping="0.038319998323206518" friction="0.021242402695969654" />
    </joint>

    <link name="left_link_3_0">
        <visual>
            <geometry>
                <mesh filename="/collision/allegro_hand/link_3.0.STL" />
            </geometry>
            <material name="black" />
        </visual>
        <collision>
            <geometry>
                <box size="0.0196 0.0275 0.0267" />
            </geometry>
            <origin rpy="0 0 0" xyz="0 0 0.01335" />
        </collision>
    </link>

    <joint name="left_joint_3_0_tip" type="fixed">
        <parent link="left_link_3_0" />
        <child link="left_link_3_0_tip" />
        <origin rpy="0 0 0" xyz="0.01335 0 0.0408" />
    </joint>

    <link name="left_link_3_0_tip">
        <visual>
            <geometry>
                <mesh filename="/collision/allegro_hand/sensing_tip.stl" scale="0.001 0.001 0.001" />
            </geometry>
            <origin rpy="1.5707963259 0 1.5707963259" xyz="-0.0095 0 0" />
            <material name="white">
                <color rgba=".9 .9 .9 1" />
            </material>
        </visual>
        <collision>
            <geometry>
                <sphere radius="0.012" />
            </geometry>
        </collision>
    </link>

    <!-- Middle -->

    <joint name="left_joint_4_0" type="revolute">
        <axis xyz="0 0 1" />
        <limit effort="0.7" lower="-0.596932245164993" upper="0.588070723111615" velocity="3" />
        <parent link="left_hand_base_link" />
        <child link="left_link_4_0" />
        <origin rpy="0.0 0 0" xyz="0 0 0.0007" />
        <dynamics damping="0.03919965995816594" friction="0.039832089332686435" />
    </joint>

    <link name="left_link_4_0">
        <visual>
            <geometry>
                <mesh filename="/collision/allegro_hand/link_0.0.STL" />
            </geometry>
            <material name="black" />
        </visual>
        <collision>
            <geometry>
                <box size="0.0196 0.0275 0.0164" />
            </geometry>
            <origin rpy="0 0 0" xyz="0 0 0.0082" />
        </collision>
    </link>

    <joint name="left_joint_5_0" type="revolute">
        <limit effort="0.7" lower="-0.284219635541756" upper="1.79806052068398" velocity="3" />
        <axis xyz="0 1 0" />
        <parent link="left_link_4_0" />
        <child link="left_link_5_0" />
        <origin xyz="0 0 0.0164" />
        <dynamics damping="0.03873626118353872" friction="0.054137945660864321" />
    </joint>

    <link name="left_link_5_0">
        <visual>
            <geometry>
                <mesh filename="/collision/allegro_hand/link_1.0.STL" />
            </geometry>
            <material name="black" />
        </visual>
        <collision>
            <geometry>
                <box size="0.0196 0.0275 0.054" />
            </geometry>
            <origin rpy="0 0 0" xyz="0 0 0.027" />
        </collision>
    </link>

    <joint name="left_joint_6_0" type="revolute">
        <axis xyz="0 1 0" />
        <limit effort="0.7" lower="-0.277444047727987" upper="1.77295534050938" velocity="3" />
        <parent link="left_link_5_0" />
        <child link="left_link_6_0" />
        <origin xyz="0 0 0.054" />
        <dynamics damping="0.038096107794554551" friction="0.016501055223839444" />
    </joint>

    <link name="left_link_6_0">
        <visual>
            <geometry>
                <mesh filename="/collision/allegro_hand/link_2.0.STL" />
            </geometry>
            <material name="black" />
        </visual>
        <collision>
            <geometry>
                <box size="0.0196 0.0275 0.0384" />
            </geometry>
            <origin rpy="0 0 0" xyz="0 0 0.0192" />
        </collision>
    </link>

    <joint name="left_joint_7_0" type="revolute">
        <axis xyz="0 1 0" />
        <limit effort="0.7" lower="-0.282000556563447" upper="1.76086875700753" velocity="3" />
        <parent link="left_link_6_0" />
        <child link="left_link_7_0" />
        <origin xyz="0 0 0.0384" />
        <dynamics damping="0.030909594496839752" friction="0.018861768610753726" />
    </joint>

    <link name="left_link_7_0">
        <visual>
            <geometry>
                <mesh filename="/collision/allegro_hand/link_3.0.STL" />
            </geometry>
            <material name="black" />
        </visual>
        <collision>
            <geometry>
                <box size="0.0196 0.0275 0.0267" />
            </geometry>
            <origin rpy="0 0 0" xyz="0 0 0.01335" />
        </collision>
    </link>

    <joint name="left_joint_7_0_tip" type="fixed">
        <parent link="left_link_7_0" />
        <child link="left_link_7_0_tip" />
        <origin rpy="0 0 0" xyz="0.01335 0 0.0408" />
    </joint>

    <link name="left_link_7_0_tip">
        <visual>
            <geometry>
                <mesh filename="/collision/allegro_hand/sensing_tip.stl" scale="0.001 0.001 0.001" />
            </geometry>
            <origin rpy="1.5707963259 0 1.5707963259" xyz="-0.0095 0 0" />
            <material name="white">
                <color rgba=".9 .9 .9 1" />
            </material>
        </visual>
        <collision>
            <geometry>
                <sphere radius="0.012" />
            </geometry>
        </collision>
    </link>

    <!-- Ring -->
    <joint name="left_joint_8_0" type="revolute">
        <axis xyz="0 0 1" />
        <limit effort="0.7" lower="-0.596932245164993" upper="0.588070723111615" velocity="3" />
        <parent link="left_hand_base_link" />
        <child link="left_link_8_0" />
        <origin rpy="-0.08726646255 0 0" xyz="0 0.0435 -0.001542" />
        <dynamics damping="0.021307336803783977" friction="0.06754533316058077" />
    </joint>

    <link name="left_link_8_0">
        <visual>
            <geometry>
                <mesh filename="/collision/allegro_hand/link_0.0.STL" />
            </geometry>
            <material name="black" />
        </visual>
        <collision>
            <geometry>
                <box size="0.0196 0.0275 0.0164" />
            </geometry>
            <origin rpy="0 0 0" xyz="0 0 0.0082" />
        </collision>
    </link>

    <joint name="left_joint_9_0" type="revolute">
        <limit effort="0.7" lower="-0.284219635541756" upper="1.79806052068398" velocity="3" />
        <axis xyz="0 1 0" />
        <parent link="left_link_8_0" />
        <child link="left_link_9_0" />
        <origin xyz="0 0 0.0164" />
        <dynamics damping="0.01767730238754802" friction="0.046834261267951538" />
    </joint>

    <link name="left_link_9_0">
        <visual>
            <geometry>
                <mesh filename="/collision/allegro_hand/link_1.0.STL" />
            </geometry>
            <material name="black" />
        </visual>
        <collision>
            <geometry>
                <box size="0.0196 0.0275 0.054" />
            </geometry>
            <origin rpy="0 0 0" xyz="0 0 0.027" />
        </collision>
    </link>

    <joint name="left_joint_10_0" type="revolute">
        <axis xyz="0 1 0" />
        <limit effort="0.7" lower="-0.277444047727987" upper="1.77295534050938" velocity="3" />
        <parent link="left_link_9_0" />
        <child link="left_link_10_0" />
        <origin xyz="0 0 0.054" />
        <dynamics damping="0.031774638864325758" friction="0.016627969777092133" />
    </joint>

    <link name="left_link_10_0">
        <visual>
            <geometry>
                <mesh filename="/collision/allegro_hand/link_2.0.STL" />
            </geometry>
            <material name="black" />
        </visual>
        <collision>
            <geometry>
                <box size="0.0196 0.0275 0.0384" />
            </geometry>
            <origin rpy="0 0 0" xyz="0 0 0.0192" />
        </collision>
    </link>

    <joint name="left_joint_11_0" type="revolute">
        <axis xyz="0 1 0" />
        <limit effort="0.7" lower="-0.282000556563447" upper="1.76086875700753" velocity="3" />
        <parent link="left_link_10_0" />
        <child link="left_link_11_0" />
        <origin xyz="0 0 0.0384" />
        <dynamics damping="0.038319998323206518" friction="0.021242402695969654" />
    </joint>

    <link name="left_link_11_0">
        <visual>
            <geometry>
                <mesh filename="/collision/allegro_hand/link_3.0.STL" />
            </geometry>
            <material name="black" />
        </visual>
        <collision>
            <geometry>
                <box size="0.0196 0.0275 0.0267" />
            </geometry>
            <origin rpy="0 0 0" xyz="0 0 0.01335" />
        </collision>
    </link>

    <joint name="left_joint_11_0_tip" type="fixed">
        <parent link="left_link_11_0" />
        <child link="left_link_11_0_tip" />
        <origin rpy="0 0 0" xyz="0.01335 0 0.0408" />
    </joint>

    <link name="left_link_11_0_tip">
        <visual>
            <geometry>
                <mesh filename="/collision/allegro_hand/sensing_tip.stl" scale="0.001 0.001 0.001" />
            </geometry>
            <origin rpy="1.5707963259 0 1.5707963259" xyz="-0.0095 0 0" />
            <material name="white">
                <color rgba=".9 .9 .9 1" />
            </material>
        </visual>
        <collision>
            <geometry>
                <sphere radius="0.012" />
            </geometry>
        </collision>
    </link>

    <!-- Thumb -->
    <joint name="left_joint_12_0" type="revolute">
        <axis xyz="+1 0 0" />
        <limit effort="0.7" lower="0.218668042522522" upper="1.53293975821553" velocity="3" />
        <parent link="left_hand_base_link" />
        <child link="left_link_12_0" />
        <origin rpy="0 -1.65806278845 1.5707963259" xyz="-0.0182 -0.019333 -0.045987" />
        <dynamics damping="0.021307336803783977" friction="0.06754533316058077" />
    </joint>

    <link name="left_link_12_0">
        <visual>
            <geometry>
                <mesh filename="/collision/allegro_hand/link_12.0_left.STL" />
            </geometry>
            <material name="black">
                <color rgba=".2 .2 .2 1" />
            </material>
            <origin rpy="3.1415926518 0 0" xyz="0 0 0" />
        </visual>
        <collision>
            <geometry>
                <box size="0.0358 0.034 0.0455" />
            </geometry>
            <origin rpy="0 0 0" xyz="-0.0179 -0.009 0.0145" />
        </collision>
    </link>

    <joint name="left_joint_13_0" type="revolute">
        <axis xyz="0 0 -1" />
        <limit effort="0.7" lower="-0.396993229219395" upper="1.20296271414105" velocity="3" />
        <parent link="left_link_12_0" />
        <child link="left_link_13_0" />
        <origin xyz="-0.027 -0.005 0.0399" />
        <dynamics damping="0.01767730238754802" friction="0.046834261267951538" />
    </joint>

    <link name="left_link_13_0">
        <visual>
            <geometry>
                <mesh filename="/collision/allegro_hand/link_13.0.STL" />
            </geometry>
            <material name="black">
                <color rgba=".2 .2 .2 1" />
            </material>
        </visual>
        <collision>
            <geometry>
                <box size="0.0196 0.0275 0.0177" />
            </geometry>
            <origin rpy="0 0 0" xyz="0 0 0.00885" />
        </collision>
    </link>

    <joint name="left_joint_14_0" type="revolute">
        <axis xyz="0 1 0" />
        <limit effort="0.7" lower="-0.251244121924091" upper="1.76700820884751" velocity="3" />
        <parent link="left_link_13_0" />
        <child link="left_link_14_0" />
        <origin xyz="0 0 0.0177" />
        <dynamics damping="0.031774638864325758" friction="0.016627969777092133" />
    </joint>

    <link name="left_link_14_0">
        <visual>
            <geometry>
                <mesh filename="/collision/allegro_hand/link_14.0.STL" />
            </geometry>
            <material name="black" />
        </visual>
        <collision>
            <geometry>
                <box size="0.0196 0.0275 0.0514" />
            </geometry>
            <origin rpy="0 0 0" xyz="0 0 0.0257" />
        </collision>
    </link>

    <joint name="left_joint_15_0" type="revolute">
        <axis xyz="0 1 0" />
        <limit effort="0.7" lower="-0.260209200996458" upper="1.82261832804392" velocity="3" />
        <parent link="left_link_14_0" />
        <child link="left_link_15_0" />
        <origin xyz="0 0 0.0514" />
        <dynamics damping="0.038319998323206518" friction="0.021242402695969654" />
    </joint>

    <link name="left_link_15_0">
        <visual>
            <geometry>
                <mesh filename="/collision/allegro_hand/link_15.0.STL" />
            </geometry>
            <material name="black" />
        </visual>
        <collision>
            <geometry>
                <box size="0.0196 0.0275 0.0423" />
            </geometry>
            <origin rpy="0 0 0" xyz="0 0 0.02115" />
        </collision>
    </link>

    <joint name="left_joint_15_0_tip" type="fixed">
        <parent link="left_link_15_0" />
        <child link="left_link_15_0_tip" />
        <origin rpy="0 0 0" xyz="0.01335 0 0.0564" />
    </joint>

    <link name="left_link_15_0_tip">
        <visual>
            <geometry>
                <mesh filename="/collision/allegro_hand/sensing_tip.stl" scale="0.001 0.001 0.001" />
            </geometry>
            <origin rpy="1.5707963259 0 1.5707963259" xyz="-0.0095 0 0" />
            <material name="white">
                <color rgba=".9 .9 .9 1" />
            </material>
        </visual>
        <collision>
            <geometry>
                <sphere radius="0.012" />
            </geometry>
            <origin rpy="0 0 0" xyz="0 0 0" />
        </collision>
    </link>

    <!-- END: HAND LEFT -->	

</robot>
